[2024-05-18T12:17:00.519+0000] {task_context_logger.py:104} ERROR - Executor reports task instance <TaskInstance: goodreads_pipeline.GoodReadsETLJob scheduled__2024-05-16T00:00:00+00:00 [queued]> finished (failed) although the task says it's queued. (Info: None) Was the task killed externally?
